{"state": "running", "total": 144, "completed": 77, "history": [], "last_error": "Error encountered with object named 'synapses_1_pre'.\nObject was created here (most recent call only, full details in debug log):\n  File '/Users/camdouglas/quark/brain_architecture/neural_core/hippocampus/ca3_recurrent.py', line 46, in build_ca3_recurrent\n    syn_dg_ca3 = Synapses(DG, CA3, model=\"\"\"\n\nAn error occurred when preparing an object. (See above for original error message and traceback.)"}